<?xml version="1.0" ?>
<robot name="daVinci">
  <gazebo reference="base">
    <material>Gazebo/GrassFloor</material>
  </gazebo>
  <link name="world"/>

  <joint name="wall_joint" type="fixed">
    <parent link="world"/>
    <origin rpy="0 0 0" xyz="0 0 0"/>
    <child link="wall_link"/>
  </joint>

  <link name="wall_link">
    <inertial>
      <mass value="0.01"/>
      <origin xyz="0 0 1.0"/>
      <inertia ixx="1.0" ixy="0.0" ixz="0.0" iyy="1.0" iyz="0.0" izz="1.0"/>
    </inertial>
    <visual>
      <origin rpy="0 0 0" xyz="0 0 0"/>
      <geometry>
        <!-- <box size="0.2 0.2 2.0"/>-->
	<mesh filename="package://daVinci/meshes/outer_pitch_base.stl"/>      
      </geometry>
    </visual>
    <collision>
      <origin rpy="0 0 0" xyz="0 0 1.0"/>
      <geometry>
        <box size="0.2 0.2 2.0"/>
      </geometry>
    </collision>
  </link>

  <joint name="base_joint" type="fixed">
    <parent link="wall_link"/>
    <origin rpy="0 0 0" xyz="0 0.1 1.5"/>
    <child link="base_link"/>
  </joint>

  <link name="base_link">
    <inertial>
      <mass value="0.01"/>
      <origin xyz="0 0.2 0"/>
      <inertia ixx="1.0" ixy="0.0" ixz="0.0" iyy="1.0" iyz="0.0" izz="1.0"/>
    </inertial>
    <visual>
      <origin rpy="0 0 0" xyz="0 0.2 0"/>
      <geometry>
        <box size="0.2 0.4 0.2"/>
      </geometry>
    </visual>
    <collision>
      <origin rpy="0 0 0" xyz="0 0.2 0"/>
      <geometry>
        <box size="0.2 0.4 0.2"/>
      </geometry>
    </collision>
  </link>

  <joint name="joint_1" type="continuous">
    <axis xyz="0 1 0"/>
    <parent link="base_link"/>
    <origin rpy="0 0 0" xyz="0 0.6 0"/>
    <child link="link_1"/>
    <dynamics damping="0.1"/>
  </joint>


  <link name="link_1">
    <inertial>
      <mass value="0.01"/>
      <origin xyz="0 0 0"/>
      <inertia ixx="1.0" ixy="0.0" ixz="0.0" iyy="1.0" iyz="0.0" izz="1.0"/>
    </inertial>
    <visual>
      <origin rpy="0 0 0" xyz="0 0 0"/>
      <geometry>
        <sphere radius="0.2"/>
      </geometry>
    </visual>
    <collision>
      <origin rpy="0 0 0" xyz="0 0 0"/>
      <geometry>
        <sphere radius="0.2"/>
      </geometry>
    </collision>
  </link>

  <joint name="joint1_struct1" type="fixed">
    <parent link="link_1"/>
    <origin rpy="0 0 0" xyz="0 0 0.2"/>
    <child link="link1_struct1"/>
  </joint>

  <link name="link1_struct1">
    <inertial>
      <mass value="0.01"/>
      <origin xyz="0 0 0.2"/>
      <inertia ixx="1.0" ixy="0.0" ixz="0.0" iyy="1.0" iyz="0.0" izz="1.0"/>
    </inertial>
    <visual>
      <origin rpy="0 0 0" xyz="0 0 0.2"/>
      <geometry>
        <box size="0.2 0.2 0.4"/>
      </geometry>
    </visual>
    <collision>
      <origin rpy="0 0 0" xyz="0 0 0.2"/>
      <geometry>
        <box size="0.2 0.2 0.4"/>
      </geometry>
    </collision>
  </link>

  <joint name="joint1_struct2" type="fixed">
    <parent link="link1_struct1"/>
    <origin rpy="0 0 0" xyz="0 0 0.4"/>
    <child link="link1_struct2"/>
  </joint>

  <link name="link1_struct2">
    <inertial>
      <mass value="0.01"/>
      <origin xyz="0 0.4 0.1"/>
      <inertia ixx="1.0" ixy="0.0" ixz="0.0" iyy="1.0" iyz="0.0" izz="1.0"/>
    </inertial>
    <visual>
      <origin rpy="0 0 0" xyz="0 0.4 0.1"/>
      <geometry>
        <box size="0.2 1.0 0.2"/>
      </geometry>
    </visual>
    <collision>
      <origin rpy="0 0 0" xyz="0 0.4 0.1"/>
      <geometry>
        <box size="0.2 1.0 0.2"/>
      </geometry>
    </collision>
  </link>

  <joint name="joint_2" type="continuous">
    <axis xyz="1 0 0"/>
    <parent link="link1_struct2"/>
    <origin rpy="0 0 0" xyz="0 0.9 0.1"/>
    <child link="link_2"/>
    <dynamics damping="0.1"/>
  </joint>

  <link name="link_2">
    <inertial>
      <mass value="0.01"/>
      <origin xyz="0 0.05 0.2"/>
      <inertia ixx="1.0" ixy="0.0" ixz="0.0" iyy="1.0" iyz="0.0" izz="1.0"/>
    </inertial>
    <visual>
      <origin rpy="0 0 0" xyz="0 0.05 0.2"/>
      <geometry>
        <box size="0.2 0.1 1.0"/>
      </geometry>
      <material name="Cyan">
       <color rgba="0 1 0 0.5"/>
      </material>    
    </visual>
    <collision>
      <origin rpy="0 0 0" xyz="0 0.05 0.2"/>
      <geometry>
        <box size="0.2 0.1 1.0"/>
      </geometry>
    </collision>
  </link>

  <joint name="joint2_struct1" type="fixed">
    <parent link="link_2"/>
    <origin rpy="0 0 0" xyz="0 0.1 0"/>
    <child link="link2_struct1"/>
  </joint>

  <link name="link2_struct1">
    <inertial>
      <mass value="0.01"/>
      <origin xyz="0 0.05 0.2"/>
      <inertia ixx="1.0" ixy="0.0" ixz="0.0" iyy="1.0" iyz="0.0" izz="1.0"/>
    </inertial>
    <visual>
      <origin rpy="0 0 0" xyz="0 0.05 0.2"/>
      <geometry>
        <box size="0.2 0.1 1.0"/>
      </geometry>
    </visual>
    <collision>
      <origin rpy="0 0 0" xyz="0 0.05 0.2"/>
      <geometry>
        <box size="0.2 0.1 1.0"/>
      </geometry>
    </collision>
  </link>

  <joint name="joint_3" type="prismatic">
    <axis xyz="0 0 1"/>
    <parent link="link2_struct1"/>
    <origin rpy="0 0 0" xyz="0 0.05 0"/>
    <child link="link_3"/>
    <dynamics damping="0.1"/>
    <limit effort="30" velocity="1.0" lower="-0.5" upper="0.5"/>
  </joint>

  <link name="link_3">
    <inertial>
      <mass value="0.01"/>
      <origin xyz="0 0 -0.1"/>
      <inertia ixx="1.0" ixy="0.0" ixz="0.0" iyy="1.0" iyz="0.0" izz="1.0"/>
    </inertial>
    <visual>
      <origin rpy="0 0 0" xyz="0 0 -0.1"/>
      <geometry>
        <cylinder radius="0.02" length="1.2"/>
      </geometry>
    </visual>
    <collision>
      <origin rpy="0 0 0" xyz="0 0 -0.1"/>
      <geometry>
        <cylinder radius="0.02" length="1.2"/>
      </geometry>
    </collision>
  </link>

  <gazebo reference="wall_link">
    <material>Gazebo/GrassFloor</material>
    <turnGravityOff>false</turnGravityOff>
  </gazebo>
</robot>




